{
  "nbformat": 4,
  "nbformat_minor": 0,
  "metadata": {
    "colab": {
      "name": "FaceBlur_Server.ipynb",
      "provenance": [],
      "collapsed_sections": []
    },
    "kernelspec": {
      "name": "python3",
      "display_name": "Python 3"
    }
  },
  "cells": [
    {
      "cell_type": "code",
      "metadata": {
        "colab": {
          "base_uri": "https://localhost:8080/"
        },
        "id": "T_6emKkzsEZo",
        "outputId": "341617a3-7ac0-4c03-a306-37be66ea5689"
      },
      "source": [
        "!git clone https://github.com/anthonysbr/FaceApp-backend.git\n",
        "%cd FaceApp-backend\n",
        "!pip install -r requirements.txt -q"
      ],
      "execution_count": 2,
      "outputs": [
        {
          "output_type": "stream",
          "text": [
            "Cloning into 'faceblur-app'...\n",
            "remote: Enumerating objects: 42, done.\u001b[K\n",
            "remote: Counting objects: 100% (42/42), done.\u001b[K\n",
            "remote: Compressing objects: 100% (33/33), done.\u001b[K\n",
            "remote: Total 42 (delta 8), reused 39 (delta 5), pack-reused 0\u001b[K\n",
            "Unpacking objects: 100% (42/42), done.\n",
            "/content/faceblur-app\n",
            "\u001b[K     |████████████████████████████████| 421.8MB 29kB/s \n",
            "\u001b[K     |████████████████████████████████| 5.6MB 20.8MB/s \n",
            "\u001b[K     |████████████████████████████████| 163kB 11.5MB/s \n",
            "\u001b[K     |████████████████████████████████| 51kB 5.8MB/s \n",
            "\u001b[K     |████████████████████████████████| 3.9MB 32.3MB/s \n",
            "\u001b[K     |████████████████████████████████| 450kB 51.0MB/s \n",
            "\u001b[K     |████████████████████████████████| 245kB 41.9MB/s \n",
            "\u001b[K     |████████████████████████████████| 163kB 43.9MB/s \n",
            "\u001b[?25h  Building wheel for cloudinary (setup.py) ... \u001b[?25l\u001b[?25hdone\n",
            "  Building wheel for gast (setup.py) ... \u001b[?25l\u001b[?25hdone\n",
            "\u001b[31mERROR: tensorflow 2.4.1 has requirement gast==0.3.3, but you'll have gast 0.2.2 which is incompatible.\u001b[0m\n",
            "\u001b[31mERROR: tensorflow 2.4.1 has requirement tensorboard~=2.4, but you'll have tensorboard 2.1.1 which is incompatible.\u001b[0m\n",
            "\u001b[31mERROR: tensorflow 2.4.1 has requirement tensorflow-estimator<2.5.0,>=2.4.0, but you'll have tensorflow-estimator 2.1.0 which is incompatible.\u001b[0m\n",
            "\u001b[31mERROR: tensorflow-probability 0.12.1 has requirement gast>=0.3.2, but you'll have gast 0.2.2 which is incompatible.\u001b[0m\n"
          ],
          "name": "stdout"
        }
      ]
    },
    {
      "cell_type": "code",
      "metadata": {
        "colab": {
          "base_uri": "https://localhost:8080/"
        },
        "id": "1r1rfXE5tDKK",
        "outputId": "12d132f3-7fd5-4631-d8e7-504a80c8c0cb"
      },
      "source": [
        "!python flask_app.py"
      ],
      "execution_count": 9,
      "outputs": [
        {
          "output_type": "stream",
          "text": [
            "2021-03-08 15:11:37.318807: W tensorflow/stream_executor/platform/default/dso_loader.cc:55] Could not load dynamic library 'libnvinfer.so.6'; dlerror: libnvinfer.so.6: cannot open shared object file: No such file or directory; LD_LIBRARY_PATH: /usr/local/nvidia/lib:/usr/local/nvidia/lib64\n",
            "2021-03-08 15:11:37.319023: W tensorflow/stream_executor/platform/default/dso_loader.cc:55] Could not load dynamic library 'libnvinfer_plugin.so.6'; dlerror: libnvinfer_plugin.so.6: cannot open shared object file: No such file or directory; LD_LIBRARY_PATH: /usr/local/nvidia/lib:/usr/local/nvidia/lib64\n",
            "2021-03-08 15:11:37.319044: W tensorflow/compiler/tf2tensorrt/utils/py_utils.cc:30] Cannot dlopen some TensorRT libraries. If you would like to use Nvidia GPU with TensorRT, please make sure the missing libraries mentioned above are installed properly.\n",
            "/usr/local/lib/python3.7/dist-packages/keras_applications/mobilenet_v2.py:294: UserWarning: `input_shape` is undefined or non-square, or `rows` is not in [96, 128, 160, 192, 224]. Weights for input shape (224, 224) will be loaded as the default.\n",
            "  warnings.warn('`input_shape` is undefined or non-square, '\n",
            "[*] load ckpt from ./checkpoints/retinaface_mbv2/ckpt-81.\n",
            " * Serving Flask app \"flask_app\" (lazy loading)\n",
            " * Environment: production\n",
            "\u001b[31m   WARNING: This is a development server. Do not use it in a production deployment.\u001b[0m\n",
            "\u001b[2m   Use a production WSGI server instead.\u001b[0m\n",
            " * Debug mode: off\n",
            " * Running on http://127.0.0.1:5000/ (Press CTRL+C to quit)\n",
            " * Running on http://c5a947bb9bd5.ngrok.io\n",
            " * Traffic stats available on http://127.0.0.1:4040\n",
            "127.0.0.1 - - [08/Mar/2021 15:12:41] \"\u001b[37mPOST /predict HTTP/1.1\u001b[0m\" 200 -\n",
            "127.0.0.1 - - [08/Mar/2021 15:13:08] \"\u001b[37mPOST /predict HTTP/1.1\u001b[0m\" 200 -\n",
            "127.0.0.1 - - [08/Mar/2021 15:13:38] \"\u001b[37mPOST /predict HTTP/1.1\u001b[0m\" 200 -\n",
            "127.0.0.1 - - [08/Mar/2021 15:14:07] \"\u001b[37mPOST /predict HTTP/1.1\u001b[0m\" 200 -\n",
            "Error in atexit._run_exitfuncs:\n",
            "Traceback (most recent call last):\n",
            "  File \"/usr/lib/python3.7/logging/__init__.py\", line 2035, in shutdown\n",
            "    h.acquire()\n",
            "  File \"/usr/lib/python3.7/logging/__init__.py\", line 842, in acquire\n",
            "    if self.lock:\n",
            "KeyboardInterrupt\n",
            "\n",
            "During handling of the above exception, another exception occurred:\n",
            "\n",
            "Traceback (most recent call last):\n",
            "  File \"/usr/lib/python3.7/logging/__init__.py\", line 2045, in shutdown\n",
            "    h.release()\n",
            "  File \"/usr/lib/python3.7/logging/__init__.py\", line 850, in release\n",
            "    self.lock.release()\n",
            "RuntimeError: cannot release un-acquired lock\n"
          ],
          "name": "stdout"
        }
      ]
    },
    {
      "cell_type": "code",
      "metadata": {
        "id": "kJ4sJnPvjU94"
      },
      "source": [],
      "execution_count": null,
      "outputs": []
    }
  ]
}